Workbook

Sheet Sheet1
A1: 序号 | B1: 采购单号 | C1: 供应商 | D1: 待上传的支付凭证名 | E1: 入库金额 | F1: 日期 | G1: 金额 | H1: 差异 | I1: 系统采购金额 | J1: 状态 | K1: 备注 | L1: 序号
A2: 1 | B2: MCG202605050065 | C2: 佛山市缤涛纺织有限公司 | E2: 13 | F2: 2026-05-06 11:07:35 | G2: =E2+H2 -> 13 | H2: 0 | I2: 13 | J2: 待上传 | K2: 仿棉拉架平纹-200G（阻燃） | L2: 1 | M2: =VLOOKUP(B2,[1]报销单!$D:$G,4,0) -> #N/A
A3: 1 | B3: MCG202605050053 | C3: 佛山市缤涛纺织有限公司 | E3: 13 | F3: 2026-05-06 11:07:20 | G3: =E3+H3 -> 13 | H3: 0 | I3: 13 | J3: 待上传 | K3: 仿棉拉架平纹-200G（阻燃） | L3: 1 | M3: =VLOOKUP(B3,[1]报销单!$D:$G,4,0) -> #N/A
A4: 1 | B4: MCG202605050054 | C4: 佛山市缤涛纺织有限公司 | E4: 13 | F4: 2026-05-06 11:07:28 | G4: =E4+H4 -> 13 | H4: 0 | I4: 13 | J4: 待上传 | K4: 仿棉拉架平纹-200G（阻燃） | L4: 1 | M4: =VLOOKUP(B4,[1]报销单!$D:$G,4,0) -> #N/A
A5: 1 | B5: MCG202605050041 | C5: 佛山市缤涛纺织有限公司 | E5: 13 | F5: 2026-05-06 11:06:57 | G5: =E5+H5 -> 13 | H5: 0 | I5: 13 | J5: 待上传 | K5: 仿棉拉架平纹-200G（阻燃） | L5: 1 | M5: =VLOOKUP(B5,[1]报销单!$D:$G,4,0) -> #N/A
A6: 1 | B6: MCG202605050038 | C6: 佛山市缤涛纺织有限公司 | E6: 13 | F6: 2026-05-06 11:07:05 | G6: =E6+H6 -> 13 | H6: 0 | I6: 13 | J6: 待上传 | K6: 仿棉拉架平纹-200G（阻燃） | L6: 1 | M6: =VLOOKUP(B6,[1]报销单!$D:$G,4,0) -> #N/A
A7: 1 | B7: MCG202605050036 | C7: 佛山市缤涛纺织有限公司 | E7: 13 | F7: 2026-05-06 11:07:12 | G7: =E7+H7 -> 13 | H7: 0 | I7: 13 | J7: 待上传 | K7: 仿棉拉架平纹-200G（阻燃） | L7: 1 | M7: =VLOOKUP(B7,[1]报销单!$D:$G,4,0) -> #N/A
A8: 1 | B8: MCG202605050025 | C8: 佛山市缤涛纺织有限公司 | E8: 13 | F8: 2026-05-06 11:07:43 | G8: =E8+H8 -> 13 | H8: 0 | I8: 13 | J8: 待上传 | K8: 仿棉拉架平纹-200G（阻燃） | L8: 1 | M8: =VLOOKUP(B8,[1]报销单!$D:$G,4,0) -> #N/A
A9: 1 | B9: MCG202605050013 | C9: 佛山市缤涛纺织有限公司 | E9: 13 | F9: 2026-05-06 11:07:51 | G9: =E9+H9 -> 13 | H9: 0 | I9: 13 | J9: 待上传 | K9: 仿棉拉架平纹-200G（阻燃） | L9: 1 | M9: =VLOOKUP(B9,[1]报销单!$D:$G,4,0) -> #N/A
A10: 2 | B10: MCG202605050073 | C10: 佛山市缤涛纺织有限公司 | E10: 13 | F10: 2026-05-06 11:08:44 | G10: =E10+H10 -> 13 | H10: 0 | I10: 13 | J10: 待上传 | K10: 涤1*1拉架罗纹-260G（阻燃） | L10: 2 | M10: =VLOOKUP(B10,[1]报销单!$D:$G,4,0) -> #N/A
A11: 2 | B11: MCG202605050068 | C11: 佛山市缤涛纺织有限公司 | E11: 13 | F11: 2026-05-06 11:00:25 | G11: =E11+H11 -> 13 | H11: 0 | I11: 13 | J11: 待上传 | K11: 涤1*1拉架罗纹-260G（阻燃） | L11: 2 | M11: =VLOOKUP(B11,[1]报销单!$D:$G,4,0) -> #N/A
A12: 2 | B12: MCG202605050067 | C12: 佛山市缤涛纺织有限公司 | E12: 13 | F12: 2026-05-06 11:00:17 | G12: =E12+H12 -> 13 | H12: 0 | I12: 13 | J12: 待上传 | K12: 涤1*1拉架罗纹-260G（阻燃） | L12: 2 | M12: =VLOOKUP(B12,[1]报销单!$D:$G,4,0) -> #N/A
A13: 2 | B13: MCG202605050066 | C13: 佛山市缤涛纺织有限公司 | E13: 26 | F13: 2026-05-06 11:00:10 | G13: =E13+H13 -> 26 | H13: 0 | I13: 26 | J13: 待上传 | K13: 涤1*1拉架罗纹-260G（阻燃） | L13: 2 | M13: =VLOOKUP(B13,[1]报销单!$D:$G,4,0) -> #N/A
... A74: 17 | B74: MCG202605260040 | C74: 佛山市缤涛纺织有限公司 | E74: 13 | F74: 2026-05-28 15:18:00 | G74: =E74+H74 -> 13 | H74: 0 | I74: 13 | J74: 待上传 | K74: 涤1*1拉架罗纹-260G（阻燃） | L74: 17 | M74: =VLOOKUP(B74,[1]报销单!$D:$G,4,0) -> #N/A
A75: 18 | B75: MCG202605280019 | C75: 佛山市缤涛纺织有限公司 | D75: 1404-佛山市缤涛纺织有限公司 | E75: 13 | F75: 2026-05-29 14:20:18 | G75: =E75+H75 -> 13 | H75: 0 | I75: 13 | J75: 待上传 | K75: 双磨牛奶丝-220G（印花底布） | L75: 18 | M75: =VLOOKUP(B75,[1]报销单!$D:$G,4,0) -> #N/A
A76: 19 | B76: MCG202606010035 | C76: 佛山市缤涛纺织有限公司 | E76: 13 | F76: 2026-06-02 13:59:32 | G76: =E76+H76 -> 13 | H76: 0 | I76: 13 | J76: 待上传 | K76: 双磨牛奶丝-200G（印花底布） | L76: 19 | M76: =VLOOKUP(B76,[1]报销单!$D:$G,4,0) -> #N/A
A77: 19 | B77: MCG202606010019 | C77: 佛山市缤涛纺织有限公司 | E77: 13 | F77: 2026-06-02 13:48:55 | G77: =E77+H77 -> 13 | H77: 0 | I77: 13 | J77: 待上传 | K77: 涤1*1拉架罗纹-260G（阻燃） | L77: 19 | M77: =VLOOKUP(B77,[1]报销单!$D:$G,4,0) -> #N/A
A78: 20 | B78: MCG202606260024 | C78: 佛山市缤涛纺织有限公司 | E78: 13 | F78: 2026-06-27 16:01:16 | G78: =E78+H78 -> 13 | H78: 0 | I78: 13 | J78: 待上传 | K78: 涤1*1拉架罗纹-260G（阻燃） | L78: 20 | M78: =VLOOKUP(B78,[1]报销单!$D:$G,4,0) -> #N/A
A79: 20 | B79: MCG202606260022 | C79: 佛山市缤涛纺织有限公司 | E79: 13 | F79: 2026-06-27 16:01:01 | G79: =E79+H79 -> 13 | H79: 0 | I79: 13 | J79: 待上传 | K79: 涤1*1拉架罗纹-260G（阻燃） | L79: 20 | M79: =VLOOKUP(B79,[1]报销单!$D:$G,4,0) -> #N/A
A80: 20 | B80: MCG202606240027 | C80: 佛山市缤涛纺织有限公司 | E80: 13 | F80: 2026-06-25 11:50:34 | G80: =E80+H80 -> 13 | H80: 0 | I80: 13 | J80: 待上传 | K80: 涤1*1拉架罗纹-260G（阻燃） | L80: 20 | M80: =VLOOKUP(B80,[1]报销单!$D:$G,4,0) -> #N/A
A81: 20 | B81: MCG202606240015 | C81: 佛山市缤涛纺织有限公司 | E81: 13 | F81: 2026-06-25 11:51:14 | G81: =E81+H81 -> 13 | H81: 0 | I81: 13 | J81: 待上传 | K81: 涤1*1拉架罗纹-260G（阻燃） | L81: 20 | M81: =VLOOKUP(B81,[1]报销单!$D:$G,4,0) -> #N/A
A82: 20 | B82: MCG202606090035 | C82: 佛山市缤涛纺织有限公司 | E82: 13 | F82: 2026-06-09 16:34:44 | G82: =E82+H82 -> 13 | H82: 0 | I82: 13 | J82: 待上传 | K82: 涤1*1拉架罗纹-260G（阻燃） | L82: 20 | M82: =VLOOKUP(B82,[1]报销单!$D:$G,4,0) -> #N/A
A83: 20 | B83: MCG202606050049 | C83: 佛山市缤涛纺织有限公司 | E83: 13 | F83: 2026-06-06 15:41:29 | G83: =E83+H83 -> 13 | H83: 0 | I83: 13 | J83: 待上传 | K83: 涤1*1拉架罗纹-260G（阻燃） | L83: 20 | M83: =VLOOKUP(B83,[1]报销单!$D:$G,4,0) -> #N/A
A84: 20 | B84: MCG202606040014 | C84: 佛山市缤涛纺织有限公司 | E84: 13 | F84: 2026-06-07 11:41:55 | G84: =E84+H84 -> 13 | H84: 0 | I84: 13 | J84: 待上传 | K84: 涤1*1拉架罗纹-260G（阻燃） | L84: 20 | M84: =VLOOKUP(B84,[1]报销单!$D:$G,4,0) -> #N/A
A85: 20 | B85: MCG202606040015 | C85: 佛山市缤涛纺织有限公司 | E85: 13 | F85: 2026-06-07 11:42:06 | G85: =E85+H85 -> 13 | H85: 0 | I85: 13 | J85: 待上传 | K85: 涤1*1拉架罗纹-260G（阻燃） | L85: 20 | M85: =VLOOKUP(B85,[1]报销单!$D:$G,4,0) -> #N/A
A86: 20 | B86: MCG202606040008 | C86: 佛山市缤涛纺织有限公司 | E86: 13 | F86: 2026-06-06 19:20:50 | G86: =E86+H86 -> 10.49 | H86: -2.51 | I86: 15.51 | J86: 待上传 | K86: 涤1*1拉架罗纹-260G（阻燃） | L86: 20 | M86: =VLOOKUP(B86,[1]报销单!$D:$G,4,0) -> #N/A
A87: 20 | B87: MCG202606030083 | C87: 佛山市缤涛纺织有限公司 | E87: 13 | F87: 2026-06-07 11:41:36 | G87: =E87+H87 -> 13 | H87: 0 | I87: 13 | J87: 待上传 | K87: 涤1*1拉架罗纹-260G（阻燃） | L87: 20 | M87: =VLOOKUP(B87,[1]报销单!$D:$G,4,0) -> #N/A
... A179: 36 | B179: MCG202606240026 | C179: 佛山市缤涛纺织有限公司 | E179: 13 | F179: 2026-06-26 10:59:30 | G179: =E179+H179 -> 13 | H179: 0 | I179: 13 | J179: 待上传 | K179: 涤1*1拉架罗纹-260G（阻燃） | L179: 36 | M179: =VLOOKUP(B179,[1]报销单!$D:$G,4,0) -> #N/A
A180: 36 | B180: MCG202606240025 | C180: 佛山市缤涛纺织有限公司 | D180: 2301-佛山市缤涛纺织有限公司 | E180: 13 | F180: 2026-06-26 10:59:38 | G180: =E180+H180 -> 13 | H180: 0 | I180: 13 | J180: 待上传 | K180: 涤1*1拉架罗纹-260G（阻燃） | L180: 36 | M180: =VLOOKUP(B180,[1]报销单!$D:$G,4,0) -> #N/A
A181: 38 | B181: MCG202606240035 | C181: 周尚诚棉纺织有限公司 | E181: 23.31 | F181: 2026-06-26 10:58:05 | G181: =E181+H181 -> 23.31 | H181: 0 | I181: 23.31 | J181: 待上传 | K181: 棉涤拉架罗纹-280G | L181: 38 | M181: =VLOOKUP(B181,[1]报销单!$D:$G,4,0) -> #N/A
A182: 39 | B182: MCG202606150008 | C182: 周尚诚棉纺织有限公司 | E182: 24.5 | F182: 2026-06-16 10:29:23 | G182: =E182+H182 -> 24.5 | H182: 0 | I182: 24.5 | J182: 待上传 | K182: 棉涤拉架平纹-180G | L182: 39 | M182: =VLOOKUP(B182,[1]报销单!$D:$G,4,0) -> #N/A
A183: 39 | B183: MCG202606150007 | C183: 周尚诚棉纺织有限公司 | E183: 23.45 | F183: 2026-06-16 10:29:11 | G183: =E183+H183 -> 23.45 | H183: 0 | I183: 23.45 | J183: 待上传 | K183: 棉涤拉架平纹-180G | L183: 39 | M183: =VLOOKUP(B183,[1]报销单!$D:$G,4,0) -> #N/A
A184: 39 | B184: MCG202606150005 | C184: 周尚诚棉纺织有限公司 | E184: 23.8 | F184: 2026-06-16 10:29:02 | G184: =E184+H184 -> 23.8 | H184: 0 | I184: 23.8 | J184: 待上传 | K184: 棉涤拉架平纹-180G | L184: 39 | M184: =VLOOKUP(B184,[1]报销单!$D:$G,4,0) -> #N/A
A185: 39 | B185: MCG202606150003 | C185: 周尚诚棉纺织有限公司 | E185: 20.3 | F185: 2026-06-16 10:28:52 | G185: =E185+H185 -> 20.3 | H185: 0 | I185: 20.3 | J185: 待上传 | K185: 棉涤拉架平纹-180G | L185: 39 | M185: =VLOOKUP(B185,[1]报销单!$D:$G,4,0) -> #N/A
A186: 39 | B186: MCG202606150002 | C186: 周尚诚棉纺织有限公司 | E186: 23.46 | F186: 2026-06-16 10:28:42 | G186: =E186+H186 -> 23.46 | H186: 0 | I186: 23.46 | J186: 待上传 | K186: 棉涤拉架平纹-180G | L186: 39 | M186: =VLOOKUP(B186,[1]报销单!$D:$G,4,0) -> #N/A
A187: 40 | B187: MCG202606090036 | C187: 周尚诚棉纺织有限公司 | E187: 17.39 | F187: 2026-06-11 09:46:58 | G187: =E187+H187 -> 17.39 | H187: 0 | I187: 17.39 | J187: 待上传 | K187: 棉涤拉架罗纹-280G | L187: 40 | M187: =VLOOKUP(B187,[1]报销单!$D:$G,4,0) -> #N/A
A188: 41 | B188: MCG202606050029 | C188: 周尚诚棉纺织有限公司 | E188: 19.6 | F188: 2026-06-06 14:47:48 | G188: =E188+H188 -> 19.6 | H188: 0 | I188: 19.6 | J188: 待上传 | K188: 棉涤拉架平纹-180G | L188: 41 | M188: =VLOOKUP(B188,[1]报销单!$D:$G,4,0) -> #N/A
A189: 41 | B189: MCG202606050028 | C189: 周尚诚棉纺织有限公司 | E189: 22.05 | F189: 2026-06-06 14:47:10 | G189: =E189+H189 -> 22.05 | H189: 0 | I189: 22.05 | J189: 待上传 | K189: 棉涤拉架平纹-180G | L189: 41 | M189: =VLOOKUP(B189,[1]报销单!$D:$G,4,0) -> #N/A
A190: 41 | B190: MCG202606050024 | C190: 周尚诚棉纺织有限公司 | E190: 16.45 | F190: 2026-06-06 14:47:19 | G190: =E190+H190 -> 16.45 | H190: 0 | I190: 16.45 | J190: 待上传 | K190: 棉涤拉架平纹-180G | L190: 41 | M190: =VLOOKUP(B190,[1]报销单!$D:$G,4,0) -> #N/A
A191: 41 | B191: MCG202606050026 | C191: 周尚诚棉纺织有限公司 | E191: 16.45 | F191: 2026-06-06 14:47:58 | G191: =E191+H191 -> 16.45 | H191: 0 | I191: 16.45 | J191: 待上传 | K191: 棉涤拉架平纹-180G | L191: 41 | M191: =VLOOKUP(B191,[1]报销单!$D:$G,4,0) -> #N/A
...

Sheet 序号分组明细
A1: 序号/序号组合 | B1: 待上传的支付凭证名 | C1: 采购行数 | D1: 分组金额合计 | E1: 供应商 | F1: 采购单号/状态
A2: 1 | B2: 104-佛山市缤涛纺织有限公司 | C2: 8 | D2: 104 | E2: 佛山市缤涛纺织有限公司 | F2: MCG202605050065,MCG202605050053,MCG202605050054,MCG202605050041,MCG202605050038,MCG202605050036,MCG202605050025,MCG202605050013
A3: 2 | B3: 182-佛山市缤涛纺织有限公司 | C3: 13 | D3: 182 | E3: 佛山市缤涛纺织有限公司 | F3: MCG202605050073,MCG202605050068,MCG202605050067,MCG202605050066,MCG202605050062,MCG202605050052,MCG202605050049,MCG202605050040,MCG202605050034,MCG202605050024,MCG202605050019,MCG202605050018,MCG202605050012
A4: 3 | B4: 208-佛山市缤涛纺织有限公司 | C4: 11 | D4: 208 | E4: 佛山市缤涛纺织有限公司 | F4: MCG202605050069,MCG202605050071,MCG202605050063,MCG202605050064,MCG202605050050,MCG202605050051,MCG202605050039,MCG202605050037,MCG202605050033,MCG202605050035,MCG202605050011
A5: 4 | C5: 3 | D5: 39 | E5: 佛山市缤涛纺织有限公司 | F5: MCG202605060036,MCG202605060033,MCG202605060007
A6: 5 | C6: 2 | D6: 26 | E6: 佛山市缤涛纺织有限公司 | F6: MCG202605070014,MCG202605070011
A7: 6 | C7: 2 | D7: 26 | E7: 佛山市缤涛纺织有限公司 | F7: MCG202605080011,MCG202605080004
A8: 7 | C8: 3 | D8: 39 | E8: 佛山市缤涛纺织有限公司 | F8: MCG202605110046,MCG202605110044,MCG202605110001
A9: 8 | C9: 1 | D9: 65 | E9: 佛山市缤涛纺织有限公司 | F9: MCG202605110052
A10: 9 | C10: 5 | D10: 91 | E10: 佛山市缤涛纺织有限公司 | F10: MCG202605130038,MCG202605130036,MCG202605120027,MCG202605120028,MCG202605120026
A11: 10 | C11: 1 | D11: 13 | E11: 佛山市缤涛纺织有限公司 | F11: MCG202605140036
A12: 11 | C12: 4 | D12: 52 | E12: 佛山市缤涛纺织有限公司 | F12: MCG202605150013,MCG202605150011,MCG202605150012,MCG202605150008
A13: 12 | C13: 5 | D13: 65 | E13: 佛山市缤涛纺织有限公司 | F13: MCG202605180005,MCG202605180006,MCG202605180007,MCG202605150031,MCG202605150024
A14: 13 | C14: 3 | D14: 39 | E14: 佛山市缤涛纺织有限公司 | F14: MCG202605190028,MCG202605190017,MCG202605190018
A15: 14 | C15: 1 | D15: 13 | E15: 佛山市缤涛纺织有限公司 | F15: MCG202605210014
A16: 15 | C16: 1 | D16: 26 | E16: 佛山市缤涛纺织有限公司 | F16: MCG202605250057
... A28: 27 | C28: 1 | D28: 39 | E28: 佛山市缤涛纺织有限公司 | F28: MCG202606100011
A29: 28 | B29: 2301-佛山市缤涛纺织有限公司 | C29: 4 | D29: 91 | E29: 佛山市缤涛纺织有限公司 | F29: MCG202606110009,MCG202606110010,MCG202606110006,MCG202606100030
A30: 29 | B30: 13-佛山市缤涛纺织有限公司 | C30: 1 | D30: 13 | E30: 佛山市缤涛纺织有限公司 | F30: MCG202606260083
A31: 30 | B31: 13-2-佛山市缤涛纺织有限公司 | C31: 1 | D31: 13 | E31: 佛山市缤涛纺织有限公司 | F31: MCG202606120008
A32: 31 | B32: 65-佛山市缤涛纺织有限公司 | C32: 3 | D32: 65 | E32: 佛山市缤涛纺织有限公司 | F32: MCG202606160002,MCG202606160005,MCG202606160006
A33: 32 | B33: 299-佛山市缤涛纺织有限公司 | C33: 9 | D33: 299 | E33: 佛山市缤涛纺织有限公司 | F33: MCG202606160003,MCG202606160004,MCG202606160007,MCG202606150009,MCG202606150010,MCG202606150011,MCG202606150012,MCG202606150013,MCG202606150014
A34: 33 | B34: 91-佛山市缤涛纺织有限公司 | C34: 4 | D34: 91 | E34: 佛山市缤涛纺织有限公司 | F34: MCG202606180017,MCG202606170033,MCG202606170034,MCG202606170035
A35: 34 | B35: 26-佛山市缤涛纺织有限公司 | C35: 1 | D35: 26 | E35: 佛山市缤涛纺织有限公司 | F35: MCG202606220001
A36: 35 | B36: 52-佛山市缤涛纺织有限公司 | C36: 2 | D36: 52 | E36: 佛山市缤涛纺织有限公司 | F36: MCG202606240013,MCG202606240001
A37: 36 | B37: 91-2-佛山市缤涛纺织有限公司 | C37: 6 | D37: 91 | E37: 佛山市缤涛纺织有限公司 | F37: MCG202606240034,MCG202606240030,MCG202606240029,MCG202606240028,MCG202606240026,MCG202606240025
A38: 38 | C38: 1 | D38: 23.31 | E38: 周尚诚棉纺织有限公司 | F38: MCG202606240035
A39: 39 | C39: 5 | D39: 115.51 | E39: 周尚诚棉纺织有限公司 | F39: MCG202606150008,MCG202606150007,MCG202606150005,MCG202606150003,MCG202606150002
A40: 40 | C40: 1 | D40: 17.39 | E40: 周尚诚棉纺织有限公司 | F40: MCG202606090036
A41: 41 | C41: 6 | D41: 109.9 | E41: 周尚诚棉纺织有限公司 | F41: MCG202606050029,MCG202606050028,MCG202606050024,MCG202606050026,MCG202606050023,MCG202606050022
A42: 42 | C42: 9 | D42: 146.07 | E42: 周尚诚棉纺织有限公司 | F42: MCG202606010089,MCG202606010088,MCG202606010086,MCG202606010085,MCG202606010024,MCG202606010022,MCG202606010005,MCG202606010003,MCG202606010004
A43: 43 | B43: 432.13-周尚诚棉纺织有限公司 | C43: 1 | D43: 19.95 | E43: 周尚诚棉纺织有限公司 | F43: MCG202606300007
A44: 44 | B44: 12-NNF拉链 | C44: 4 | D44: 12 | E44: NNF拉链 | F44: MCG202606220021,MCG202606220017,MCG202606220015,MCG202606220008
A45: 45 | B45: 14-NNF拉链 | C45: 3 | D45: 14 | E45: NNF拉链 | F45: MCG202607070045,MCG202607070036,MCG202607070018
A46: 46 | B46: 3-NNF拉链 | C46: 1 | D46: 3 | E46: NNF拉链 | F46: MCG202604270010
A47: 47 | B47: 25-小米纺织 | C47: 1 | D47: 25 | E47: 小米纺织 | F47: MCG202606250014
A48: 48 | B48: 4-永亨织带有限公司 | C48: 1 | D48: 4 | E48: 永亨织带有限公司 | F48: MCG202607030046
A49: 49 | B49: 75-杰兴（杰诺）布行 | C49: 3 | D49: 75 | E49: 杰兴（杰诺）布行 | F49: MCG202607030036,MCG202607030030,MCG202607030026
A50: 50 | B50: 50-杰兴（杰诺）布行 | C50: 1 | D50: 50 | E50: 杰兴（杰诺）布行 | F50: MCG202606300016
A51: 51 | B51: 40-优粤纺织 | C51: 1 | D51: 40 | E51: 优粤纺织 | F51: MCG202607020002
...

Sheet 改名记录
A1: 序号 | B1: 原文件名 | C1: 新文件名 | D1: 结果
A2: 18 | B2: 1404-佛山市缤涛纺织有限公司.jpg | C2: 1404-佛山市缤涛纺织有限公司.jpg | D2: 无需改名
A3: 36 | B3: 2301-佛山市缤涛纺织有限公司.jpg | C3: 2301-佛山市缤涛纺织有限公司.jpg | D3: 无需改名
A4: 43 | B4: 432.13-周尚诚棉纺织有限公司.jpg | C4: 432.13-周尚诚棉纺织有限公司.jpg | D4: 无需改名
A5: 44 | B5: 12-NNF拉链.jpg | C5: 12-NNF拉链.jpg | D5: 无需改名
A6: 45 | B6: 10-NNF拉链.jpg | C6: 10-NNF拉链.jpg | D6: 无需改名
A7: 45 | B7: 4-2-SBS-福建浔兴拉链科技股份有限公司.jpg | C7: 4-2-SBS-福建浔兴拉链科技股份有限公司.jpg | D7: 无需改名
A8: 46 | B8: 3-NNF拉链.jpg | C8: 3-NNF拉链.jpg | D8: 无需改名
A9: 47 | B9: 25-小米纺织.jpg | C9: 25-小米纺织.jpg | D9: 无需改名
A10: 48 | B10: 4-永亨织带有限公司.jpg | C10: 4-永亨织带有限公司.jpg | D10: 无需改名
A11: 49 | B11: 75-杰兴（杰诺）布行.jpg | C11: 75-杰兴（杰诺）布行.jpg | D11: 无需改名
A12: 50 | B12: 50-杰兴（杰诺）布行.jpg | C12: 50-杰兴（杰诺）布行.jpg | D12: 无需改名
A13: 51 | B13: 40-优粤纺织.jpg | C13: 40-优粤纺织.jpg | D13: 无需改名
... A43: 82 | B43: 205-怡丰布行.jpg | C43: 205-怡丰布行.jpg | D43: 无需改名
A45: 手工处理 | B45: 原文件名 | C45: 新文件名 | D45: 结果
A46: 手工 | B46: 1404-缤涛.jpg | C46: 1404-佛山市缤涛纺织有限公司.jpg | D46: 已改名
A47: 手工 | B47: 10-拉链.jpg | C47: 10-NNF拉链.jpg | D47: 已改名
A48: 手工 | B48: 4-2-拉链.jpg | C48: 4-2-SBS-福建浔兴拉链科技股份有限公司.jpg | D48: 已改名
A49: 手工 | B49: 4-带之尊.jpg | C49: 4-永亨织带有限公司.jpg | D49: 已改名
A50: 手工 | B50: 150-一品.jpg | C50: 150-创盛（宇鑫）纺织.jpg | D50: 已改名
